Workbook

Sheet Źródło
A1: Arkusz | B1: Źródło danych | C1: Opis
A2: Zasoby mieszkaniowe | B2: GUS - https://stat.gov.pl/ | C2: Zasoby mieszkaniowe ogółem w miastach i na wsi.
A3: Mieszkania oddane do użytkowania | B3: GUS - https://stat.gov.pl/ | C3: Mieszkania oddane do użytkowania ogółem.
A4: Remonty mieszkań | B4: GUS - https://stat.gov.pl/ | C4: Remonty mieszkań komunalnych (związane z podwyższeniem standardu mieszkania) - (wodociąg, kanalizacja, centralne ogrzewanie, ciepła woda, gaz sieciowy, zasoby, do których doprowadzono nowe instalacje, ocieplenie budynków)
A5: Rynkowa sprzedaż lokali mieszkalnych | B5: GUS - https://stat.gov.pl/ | C5: Liczba lokali mieszkalnych sprzedanych w ramach transakcji rynkowych.
A6: Kwota wypłaconych dodatków mieszkaniowych użytkownikom lokali | B6: GUS - https://stat.gov.pl/ | C6: Liczba i kwoty wypłaconych dodatków mieszkaniowych użytkownikom lokali.

Sheet Dane
A1: Kod | B1: Powiat | C1: Rok | D1: Zasoby mieszkaniowe (szt.) | E1: Mieszkania oddane do użytkowania (szt.) | F1: Rynkowa sprzedaż lokali mieszkalnych (szt.) | G1: Kwota wypłaconych dodatków mieszkaniowych użytkownikom lokali (zł) | H1: Remonty mieszkań komunalnych (wodociąg, kanalizacja, centralne ogrzewanie, ciepła woda, gaz sieciowy, zasoby, do których doprowadzono nowe instalacje, ocieplenie budynków) [szt.].
A2: 0201000 | B2: Powiat bolesławiecki | C2: 2013 | D2: 30511 | E2: 372 | F2: 229 | G2: 2052998 | H2: 8
A3: 0202000 | B3: Powiat dzierżoniowski | C3: 2013 | D3: 39373 | E3: 173 | F3: 270 | G3: 3221117 | H3: 40
A4: 0203000 | B4: Powiat głogowski | C4: 2013 | D4: 31735 | E4: 413 | F4: 456 | G4: 2569925 | H4: 32
A5: 0204000 | B5: Powiat górowski | C5: 2013 | D5: 11705 | E5: 64 | F5: 0 | G5: 1084191 | H5: 0
A6: 0205000 | B6: Powiat jaworski | C6: 2013 | D6: 17690 | E6: 113 | F6: 85 | G6: 1280681 | H6: 4
A7: 0206000 | B7: Powiat karkonoski | C7: 2013 | D7: 23955 | E7: 281 | F7: 216 | G7: 1419745 | H7: 13
A8: 0207000 | B8: Powiat kamiennogórski | C8: 2013 | D8: 16628 | E8: 79 | F8: 87 | G8: 1132871 | H8: 20
A9: 0208000 | B9: Powiat kłodzki | C9: 2013 | D9: 63223 | E9: 404 | F9: 491 | G9: 5581123 | H9: 494
A10: 0209000 | B10: Powiat legnicki | C10: 2013 | D10: 17623 | E10: 216 | F10: 68 | G10: 1009016 | H10: 12
A11: 0210000 | B11: Powiat lubański | C11: 2013 | D11: 19897 | E11: 128 | F11: 127 | G11: 1545510 | H11: 24
A12: 0211000 | B12: Powiat lubiński | C12: 2013 | D12: 39152 | E12: 436 | F12: 533 | G12: 1749842 | H12: 54
A13: 0212000 | B13: Powiat lwówecki | C13: 2013 | D13: 16577 | E13: 78 | F13: 69 | G13: 972369 | H13: 7
... A381: 3263000 | B381: Powiat m. Świnoujście | C381: 2013 | D381: 20042 | E381: 96 | F381: 170 | G381: 1118002 | H381: 0
A382: 0201000 | B382: Powiat bolesławiecki | C382: 2014 | D382: 30770 | E382: 287 | F382: 117 | G382: 2034192 | H382: -
A383: 0202000 | B383: Powiat dzierżoniowski | C383: 2014 | D383: 39451 | E383: 95 | F383: 234 | G383: 3056046 | H383: -
A384: 0203000 | B384: Powiat głogowski | C384: 2014 | D384: 31928 | E384: 279 | F384: 438 | G384: 2404462 | H384: -
A385: 0204000 | B385: Powiat górowski | C385: 2014 | D385: 11741 | E385: 48 | F385: 3 | G385: 1021695 | H385: -
A386: 0205000 | B386: Powiat jaworski | C386: 2014 | D386: 17753 | E386: 75 | F386: 73 | G386: 1122611 | H386: -
A387: 0206000 | B387: Powiat karkonoski | C387: 2014 | D387: 24352 | E387: 420 | F387: 253 | G387: 1304185 | H387: -
A388: 0207000 | B388: Powiat kamiennogórski | C388: 2014 | D388: 16675 | E388: 58 | F388: 92 | G388: 1282224 | H388: -
A389: 0208000 | B389: Powiat kłodzki | C389: 2014 | D389: 63580 | E389: 391 | F389: 514 | G389: 5423943 | H389: -
A390: 0209000 | B390: Powiat legnicki | C390: 2014 | D390: 17836 | E390: 248 | F390: 74 | G390: 936210 | H390: -
A391: 0210000 | B391: Powiat lubański | C391: 2014 | D391: 20015 | E391: 131 | F391: 180 | G391: 1405228 | H391: -
A392: 0211000 | B392: Powiat lubiński | C392: 2014 | D392: 39495 | E392: 377 | F392: 525 | G392: 1887265 | H392: -
A393: 0212000 | B393: Powiat lwówecki | C393: 2014 | D393: 16633 | E393: 59 | F393: 71 | G393: 967033 | H393: -
... A761: 3263000 | B761: Powiat m. Świnoujście | C761: 2014 | D761: 20180 | E761: 153 | F761: 218 | G761: 1096781 | H761: -
A762: 0201000 | B762: Powiat bolesławiecki | C762: 2015 | D762: 31018 | E762: 264 | F762: 310 | G762: 1770129 | H762: 30
A763: 0202000 | B763: Powiat dzierżoniowski | C763: 2015 | D763: 39502 | E763: 63 | F763: 330 | G763: 2795949 | H763: 0
A764: 0203000 | B764: Powiat głogowski | C764: 2015 | D764: 32122 | E764: 228 | F764: 391 | G764: 2220931 | H764: 58
A765: 0204000 | B765: Powiat górowski | C765: 2015 | D765: 11796 | E765: 58 | F765: 13 | G765: 945128 | H765: 0
A766: 0205000 | B766: Powiat jaworski | C766: 2015 | D766: 17817 | E766: 76 | F766: 89 | G766: 911763 | H766: 39
A767: 0206000 | B767: Powiat karkonoski | C767: 2015 | D767: 24734 | E767: 419 | F767: 333 | G767: 1183125 | H767: 8
A768: 0207000 | B768: Powiat kamiennogórski | C768: 2015 | D768: 16718 | E768: 50 | F768: 125 | G768: 1247130 | H768: 0
A769: 0208000 | B769: Powiat kłodzki | C769: 2015 | D769: 63765 | E769: 218 | F769: 493 | G769: 4887851 | H769: 756
A770: 0209000 | B770: Powiat legnicki | C770: 2015 | D770: 17988 | E770: 188 | F770: 95 | G770: 793552 | H770: 22
A771: 0210000 | B771: Powiat lubański | C771: 2015 | D771: 20119 | E771: 108 | F771: 163 | G771: 1214265 | H771: 15
A772: 0211000 | B772: Powiat lubiński | C772: 2015 | D772: 39860 | E772: 388 | F772: 453 | G772: 1811491 | H772: 22
A773: 0212000 | B773: Powiat lwówecki | C773: 2015 | D773: 16686 | E773: 56 | F773: 44 | G773: 834095 | H773: 12
... A1521: 3263000 | B1521: Powiat m. Świnoujście | C1521: 2016 | D1521: 20393 | E1521: 112 | F1521: 253 | G1521: 1033020 | H1521: 0
...

Sheet Wskaźniki analityczne
A1: Kod | B1: Powiat | C1: Indeks dynamiki zasobów mieszkaniowych (szt.) (2013/2023) | D1: Indeks dynamiki mieszkań oddanych do użytkowania (szt.) (2013/2023) | E1: Indeks dynamiki rynkowej sprzedaży lokali mieszkalnych (szt.) (2013/2023) | F1: Indeks dynamiki kwoty wypłaconych dodatków mieszkaniowych użytkownikom lokali (szt.) (2013/2023) | G1: Średnia ilość remontów mieszkań komunalnych (2013 - 2022)
A2: 0201000 | B2: Powiat bolesławiecki | C2: =(Dane!D3802-Dane!D2)/Dane!D2 -> 0.15666481 | D2: =(Dane!E3802-Dane!E2)/Dane!E2 -> 0.067204301 | E2: =(Dane!F3802-Dane!F2)/Dane!F2 -> 1.1834061 | F2: =(Dane!G3802-Dane!G2)/Dane!G2 -> -0.26890333 | G2: =AVERAGE(Dane!H2,Dane!H762,Dane!H1142,Dane!H1902,Dane!H2662,Dane!H3422) -> 11.666667
A3: 0202000 | B3: Powiat dzierżoniowski | C3: =(Dane!D3803-Dane!D3)/Dane!D3 -> 0.046935717 | D3: =(Dane!E3803-Dane!E3)/Dane!E3 -> 1.1907514 | E3: =(Dane!F3803-Dane!F3)/Dane!F3 -> 0.9037037 | F3: =(Dane!G3803-Dane!G3)/Dane!G3 -> -0.061252665 | G3: =AVERAGE(Dane!H3,Dane!H763,Dane!H1143,Dane!H1903,Dane!H2663,Dane!H3423) -> 69.166667
A4: 0203000 | B4: Powiat głogowski | C4: =(Dane!D3804-Dane!D4)/Dane!D4 -> 0.096423507 | D4: =(Dane!E3804-Dane!E4)/Dane!E4 -> -0.49636804 | E4: =(Dane!F3804-Dane!F4)/Dane!F4 -> 0.15131579 | F4: =(Dane!G3804-Dane!G4)/Dane!G4 -> 0.12727142 | G4: =AVERAGE(Dane!H4,Dane!H764,Dane!H1144,Dane!H1904,Dane!H2664,Dane!H3424) -> 68.5
A5: 0204000 | B5: Powiat górowski | C5: =(Dane!D3805-Dane!D5)/Dane!D5 -> 0.053310551 | D5: =(Dane!E3805-Dane!E5)/Dane!E5 -> 0.125 | E5: - | F5: =(Dane!G3805-Dane!G5)/Dane!G5 -> -0.37998655 | G5: =AVERAGE(Dane!H5,Dane!H765,Dane!H1145,Dane!H1905,Dane!H2665,Dane!H3425) -> 14.166667
A6: 0205000 | B6: Powiat jaworski | C6: =(Dane!D3806-Dane!D6)/Dane!D6 -> 0.058564161 | D6: =(Dane!E3806-Dane!E6)/Dane!E6 -> 0.25663717 | E6: =(Dane!F3806-Dane!F6)/Dane!F6 -> 1.6470588 | F6: =(Dane!G3806-Dane!G6)/Dane!G6 -> -0.43494984 | G6: =AVERAGE(Dane!H6,Dane!H766,Dane!H1146,Dane!H1906,Dane!H2666,Dane!H3426) -> 14.666667
A7: 0206000 | B7: Powiat karkonoski | C7: =(Dane!D3807-Dane!D7)/Dane!D7 -> 0.15291171 | D7: =(Dane!E3807-Dane!E7)/Dane!E7 -> 0.56227758 | E7: =(Dane!F3807-Dane!F7)/Dane!F7 -> 1.6944444 | F7: =(Dane!G3807-Dane!G7)/Dane!G7 -> -0.39824898 | G7: =AVERAGE(Dane!H7,Dane!H767,Dane!H1147,Dane!H1907,Dane!H2667,Dane!H3427) -> 32.833333
A8: 0207000 | B8: Powiat kamiennogórski | C8: =(Dane!D3808-Dane!D8)/Dane!D8 -> 0.034459947 | D8: =(Dane!E3808-Dane!E8)/Dane!E8 -> 0.32911392 | E8: =(Dane!F3808-Dane!F8)/Dane!F8 -> 1.1494253 | F8: =(Dane!G3808-Dane!G8)/Dane!G8 -> -0.17176536 | G8: =AVERAGE(Dane!H8,Dane!H768,Dane!H1148,Dane!H1908,Dane!H2668,Dane!H3428) -> 4.3333333
A9: 0208000 | B9: Powiat kłodzki | C9: =(Dane!D3809-Dane!D9)/Dane!D9 -> 0.056055549 | D9: =(Dane!E3809-Dane!E9)/Dane!E9 -> 0.017326733 | E9: =(Dane!F3809-Dane!F9)/Dane!F9 -> 0.41955193 | F9: =(Dane!G3809-Dane!G9)/Dane!G9 -> -0.19376728 | G9: =AVERAGE(Dane!H9,Dane!H769,Dane!H1149,Dane!H1909,Dane!H2669,Dane!H3429) -> 331.5
A10: 0209000 | B10: Powiat legnicki | C10: =(Dane!D3810-Dane!D10)/Dane!D10 -> 0.15076888 | D10: =(Dane!E3810-Dane!E10)/Dane!E10 -> 0.65740741 | E10: =(Dane!F3810-Dane!F10)/Dane!F10 -> 2.4264706 | F10: =(Dane!G3810-Dane!G10)/Dane!G10 -> -0.3529617 | G10: =AVERAGE(Dane!H10,Dane!H770,Dane!H1150,Dane!H1910,Dane!H2670,Dane!H3430) -> 26.166667
A11: 0210000 | B11: Powiat lubański | C11: =(Dane!D3811-Dane!D11)/Dane!D11 -> 0.072724531 | D11: =(Dane!E3811-Dane!E11)/Dane!E11 -> 0.0703125 | E11: =(Dane!F3811-Dane!F11)/Dane!F11 -> 1.1968504 | F11: =(Dane!G3811-Dane!G11)/Dane!G11 -> -0.47064982 | G11: =AVERAGE(Dane!H11,Dane!H771,Dane!H1151,Dane!H1911,Dane!H2671,Dane!H3431) -> 14.833333
A12: 0211000 | B12: Powiat lubiński | C12: =(Dane!D3812-Dane!D12)/Dane!D12 -> 0.12254802 | D12: =(Dane!E3812-Dane!E12)/Dane!E12 -> 0.13302752 | E12: =(Dane!F3812-Dane!F12)/Dane!F12 -> 0.75797373 | F12: =(Dane!G3812-Dane!G12)/Dane!G12 -> 0.099380973 | G12: =AVERAGE(Dane!H12,Dane!H772,Dane!H1152,Dane!H1912,Dane!H2672,Dane!H3432) -> 13.333333
A13: 0212000 | B13: Powiat lwówecki | C13: =(Dane!D3813-Dane!D13)/Dane!D13 -> 0.046389576 | D13: =(Dane!E3813-Dane!E13)/Dane!E13 -> -0.33333333 | E13: =(Dane!F3813-Dane!F13)/Dane!F13 -> 0.52173913 | F13: =(Dane!G3813-Dane!G13)/Dane!G13 -> -0.36975675 | G13: =AVERAGE(Dane!H13,Dane!H773,Dane!H1153,Dane!H1913,Dane!H2673,Dane!H3433) -> 4.5
A14: 0213000 | B14: Powiat milicki | C14: =(Dane!D3814-Dane!D14)/Dane!D14 -> 0.13166088 | D14: =(Dane!E3814-Dane!E14)/Dane!E14 -> 1.43 | E14: =(Dane!F3814-Dane!F14)/Dane!F14 -> 2.1285714 | F14: =(Dane!G3814-Dane!G14)/Dane!G14 -> -0.42494262 | G14: =AVERAGE(Dane!H14,Dane!H774,Dane!H1154,Dane!H1914,Dane!H2674,Dane!H3434) -> 15.166667
A15: 0214000 | B15: Powiat oleśnicki | C15: =(Dane!D3815-Dane!D15)/Dane!D15 -> 0.18578282 | D15: =(Dane!E3815-Dane!E15)/Dane!E15 -> 1.1639723 | E15: =(Dane!F3815-Dane!F15)/Dane!F15 -> 1.3556338 | F15: =(Dane!G3815-Dane!G15)/Dane!G15 -> -0.031088997 | G15: =AVERAGE(Dane!H15,Dane!H775,Dane!H1155,Dane!H1915,Dane!H2675,Dane!H3435) -> 189.66667
A16: 0215000 | B16: Powiat oławski | C16: =(Dane!D3816-Dane!D16)/Dane!D16 -> 0.21342231 | D16: =(Dane!E3816-Dane!E16)/Dane!E16 -> -0.13888889 | E16: =(Dane!F3816-Dane!F16)/Dane!F16 -> 0.4847561 | F16: =(Dane!G3816-Dane!G16)/Dane!G16 -> -0.073348383 | G16: =AVERAGE(Dane!H16,Dane!H776,Dane!H1156,Dane!H1916,Dane!H2676,Dane!H3436) -> 10.5
A17: 0216000 | B17: Powiat polkowicki | C17: =(Dane!D3817-Dane!D17)/Dane!D17 -> 0.12336852 | D17: =(Dane!E3817-Dane!E17)/Dane!E17 -> -0.23875433 | E17: =(Dane!F3817-Dane!F17)/Dane!F17 -> 0.71895425 | F17: =(Dane!G3817-Dane!G17)/Dane!G17 -> 9.8214392e-05 | G17: =AVERAGE(Dane!H17,Dane!H777,Dane!H1157,Dane!H1917,Dane!H2677,Dane!H3437) -> 1.3333333
... A54: 0464000 | B54: Powiat m. Włocławek | C54: =(Dane!D3854-Dane!D54)/Dane!D54 -> 0.042485732 | D54: =(Dane!E3854-Dane!E54)/Dane!E54 -> -0.34117647 | E54: =(Dane!F3854-Dane!F54)/Dane!F54 -> 0.10805085 | F54: =(Dane!G3854-Dane!G54)/Dane!G54 -> 0.048539469 | G54: =AVERAGE(Dane!H54,Dane!H814,Dane!H1194,Dane!H1954,Dane!H2714,Dane!H3474) -> 89.166667
A55: 0601000 | B55: Powiat bialski | C55: =(Dane!D3855-Dane!D55)/Dane!D55 -> 0.043252956 | D55: =(Dane!E3855-Dane!E55)/Dane!E55 -> 0.19191919 | E55: - | F55: =(Dane!G3855-Dane!G55)/Dane!G55 -> -0.26742037 | G55: =AVERAGE(Dane!H55,Dane!H815,Dane!H1195,Dane!H1955,Dane!H2715,Dane!H3475) -> 23.833333
A56: 0602000 | B56: Powiat biłgorajski | C56: =(Dane!D3856-Dane!D56)/Dane!D56 -> 0.066560447 | D56: =(Dane!E3856-Dane!E56)/Dane!E56 -> 0.58937198 | E56: =(Dane!F3856-Dane!F56)/Dane!F56 -> 3.1428571 | F56: =(Dane!G3856-Dane!G56)/Dane!G56 -> -0.52349411 | G56: =AVERAGE(Dane!H56,Dane!H816,Dane!H1196,Dane!H1956,Dane!H2716,Dane!H3476) -> 6.3333333
A57: 0603000 | B57: Powiat chełmski | C57: =(Dane!D3857-Dane!D57)/Dane!D57 -> 0.00021369804 | D57: =(Dane!E3857-Dane!E57)/Dane!E57 -> -0.020408163 | E57: =(Dane!F3857-Dane!F57)/Dane!F57 -> 1.1333333 | F57: =(Dane!G3857-Dane!G57)/Dane!G57 -> -0.68488136 | G57: =AVERAGE(Dane!H57,Dane!H817,Dane!H1197,Dane!H1957,Dane!H2717,Dane!H3477) -> 1.6666667
A58: 0604000 | B58: Powiat hrubieszowski | C58: =(Dane!D3858-Dane!D58)/Dane!D58 -> -0.0084436431 | D58: =(Dane!E3858-Dane!E58)/Dane!E58 -> -0.68 | E58: =(Dane!F3858-Dane!F58)/Dane!F58 -> 0.11864407 | F58: =(Dane!G3858-Dane!G58)/Dane!G58 -> -0.21886081 | G58: =AVERAGE(Dane!H58,Dane!H818,Dane!H1198,Dane!H1958,Dane!H2718,Dane!H3478) -> 37
A59: 0605000 | B59: Powiat janowski | C59: =(Dane!D3859-Dane!D59)/Dane!D59 -> 0.014155183 | D59: =(Dane!E3859-Dane!E59)/Dane!E59 -> -0.12307692 | E59: =(Dane!F3859-Dane!F59)/Dane!F59 -> 0.47058824 | F59: =(Dane!G3859-Dane!G59)/Dane!G59 -> -0.50214853 | G59: =AVERAGE(Dane!H59,Dane!H819,Dane!H1199,Dane!H1959,Dane!H2719,Dane!H3479) -> 1.8333333
A60: 0606000 | B60: Powiat krasnostawski | C60: =(Dane!D3860-Dane!D60)/Dane!D60 -> -0.02129834 | D60: =(Dane!E3860-Dane!E60)/Dane!E60 -> -0.049382716 | E60: =(Dane!F3860-Dane!F60)/Dane!F60 -> -0.42222222 | F60: =(Dane!G3860-Dane!G60)/Dane!G60 -> -0.66622382 | G60: =AVERAGE(Dane!H60,Dane!H820,Dane!H1200,Dane!H1960,Dane!H2720,Dane!H3480) -> 10.333333
A61: 0607000 | B61: Powiat kraśnicki | C61: =(Dane!D3861-Dane!D61)/Dane!D61 -> 0.020922099 | D61: =(Dane!E3861-Dane!E61)/Dane!E61 -> 0.39130435 | E61: =(Dane!F3861-Dane!F61)/Dane!F61 -> 0.61176471 | F61: =(Dane!G3861-Dane!G61)/Dane!G61 -> -0.60282066 | G61: =AVERAGE(Dane!H61,Dane!H821,Dane!H1201,Dane!H1961,Dane!H2721,Dane!H3481) -> 15.5
A62: 0608000 | B62: Powiat lubartowski | C62: =(Dane!D3862-Dane!D62)/Dane!D62 -> 0.060544058 | D62: =(Dane!E3862-Dane!E62)/Dane!E62 -> 0.40277778 | E62: =(Dane!F3862-Dane!F62)/Dane!F62 -> 0.93103448 | F62: =(Dane!G3862-Dane!G62)/Dane!G62 -> -0.34904532 | G62: =AVERAGE(Dane!H62,Dane!H822,Dane!H1202,Dane!H1962,Dane!H2722,Dane!H3482) -> 2.3333333
A63: 0609000 | B63: Powiat lubelski | C63: =(Dane!D3863-Dane!D63)/Dane!D63 -> 0.18227843 | D63: =(Dane!E3863-Dane!E63)/Dane!E63 -> 0.39855072 | E63: =(Dane!F3863-Dane!F63)/Dane!F63 -> 1.3551402 | F63: =(Dane!G3863-Dane!G63)/Dane!G63 -> -0.51124557 | G63: =AVERAGE(Dane!H63,Dane!H823,Dane!H1203,Dane!H1963,Dane!H2723,Dane!H3483) -> 10.166667
A64: 0610000 | B64: Powiat łęczyński | C64: =(Dane!D3864-Dane!D64)/Dane!D64 -> 0.10066781 | D64: =(Dane!E3864-Dane!E64)/Dane!E64 -> 0.13488372 | E64: =(Dane!F3864-Dane!F64)/Dane!F64 -> 0.37037037 | F64: =(Dane!G3864-Dane!G64)/Dane!G64 -> -0.32203186 | G64: =AVERAGE(Dane!H64,Dane!H824,Dane!H1204,Dane!H1964,Dane!H2724,Dane!H3484) -> 2.8333333
A65: 0611000 | B65: Powiat łukowski | C65: =(Dane!D3865-Dane!D65)/Dane!D65 -> 0.091859253 | D65: =(Dane!E3865-Dane!E65)/Dane!E65 -> 1.6763285 | E65: =(Dane!F3865-Dane!F65)/Dane!F65 -> 4.106383 | F65: =(Dane!G3865-Dane!G65)/Dane!G65 -> -0.21995768 | G65: =AVERAGE(Dane!H65,Dane!H825,Dane!H1205,Dane!H1965,Dane!H2725,Dane!H3485) -> 16.333333
A66: 0612000 | B66: Powiat opolski | C66: =(Dane!D3866-Dane!D66)/Dane!D66 -> 0.010965551 | D66: =(Dane!E3866-Dane!E66)/Dane!E66 -> 0.42666667 | E66: =(Dane!F3866-Dane!F66)/Dane!F66 -> 0.095238095 | F66: =(Dane!G3866-Dane!G66)/Dane!G66 -> -0.1474801 | G66: =AVERAGE(Dane!H66,Dane!H826,Dane!H1206,Dane!H1966,Dane!H2726,Dane!H3486) -> 3.1666667
A67: 0613000 | B67: Powiat parczewski | C67: =(Dane!D3867-Dane!D67)/Dane!D67 -> 0.015103153 | D67: =(Dane!E3867-Dane!E67)/Dane!E67 -> -0.19767442 | E67: =(Dane!F3867-Dane!F67)/Dane!F67 -> 2.8461538 | F67: =(Dane!G3867-Dane!G67)/Dane!G67 -> -0.60527785 | G67: =AVERAGE(Dane!H67,Dane!H827,Dane!H1207,Dane!H1967,Dane!H2727,Dane!H3487) -> 14.333333
... A106: 1014000 | B106: Powiat sieradzki | C106: =(Dane!D3906-Dane!D106)/Dane!D106 -> 0.054754157 | D106: =(Dane!E3906-Dane!E106)/Dane!E106 -> 1.1947368 | E106: =(Dane!F3906-Dane!F106)/Dane!F106 -> 0.46405229 | F106: =(Dane!G3906-Dane!G106)/Dane!G106 -> -0.39267515 | G106: =AVERAGE(Dane!H106,Dane!H866,Dane!H1246,Dane!H2006,Dane!H2766,Dane!H3526) -> 13.833333
A107: 1015000 | B107: Powiat skierniewicki | C107: =(Dane!D3907-Dane!D107)/Dane!D107 -> 0.071860754 | D107: =(Dane!E3907-Dane!E107)/Dane!E107 -> -0.014388489 | E107: - | F107: =(Dane!G3907-Dane!G107)/Dane!G107 -> 0.49075797 | G107: =AVERAGE(Dane!H107,Dane!H867,Dane!H1247,Dane!H2007,Dane!H2767,Dane!H3527) -> 2.8333333
A108: 1016000 | B108: Powiat tomaszowski | C108: =(Dane!D3908-Dane!D108)/Dane!D108 -> 0.047713188 | D108: =(Dane!E3908-Dane!E108)/Dane!E108 -> 0.52961672 | E108: =(Dane!F3908-Dane!F108)/Dane!F108 -> 1.2686567 | F108: =(Dane!G3908-Dane!G108)/Dane!G108 -> 0.25210583 | G108: =AVERAGE(Dane!H108,Dane!H868,Dane!H1248,Dane!H2008,Dane!H2768,Dane!H3528) -> 40
A109: 1017000 | B109: Powiat wieluński | C109: =(Dane!D3909-Dane!D109)/Dane!D109 -> 0.074003113 | D109: =(Dane!E3909-Dane!E109)/Dane!E109 -> 0.65540541 | E109: =(Dane!F3909-Dane!F109)/Dane!F109 -> 1.3863636 | F109: =(Dane!G3909-Dane!G109)/Dane!G109 -> -0.015282988 | G109: =AVERAGE(Dane!H109,Dane!H869,Dane!H1249,Dane!H2009,Dane!H2769,Dane!H3529) -> 14.5
A110: 1018000 | B110: Powiat wieruszowski | C110: =(Dane!D3910-Dane!D110)/Dane!D110 -> 0.09632504 | D110: =(Dane!E3910-Dane!E110)/Dane!E110 -> 0.83529412 | E110: =(Dane!F3910-Dane!F110)/Dane!F110 -> 3.9411765 | F110: =(Dane!G3910-Dane!G110)/Dane!G110 -> -0.19033378 | G110: =AVERAGE(Dane!H110,Dane!H870,Dane!H1250,Dane!H2010,Dane!H2770,Dane!H3530) -> 0.16666667
A111: 1019000 | B111: Powiat zduńskowolski | C111: =(Dane!D3911-Dane!D111)/Dane!D111 -> 0.072187978 | D111: =(Dane!E3911-Dane!E111)/Dane!E111 -> 1.2222222 | E111: =(Dane!F3911-Dane!F111)/Dane!F111 -> 1.2747253 | F111: =(Dane!G3911-Dane!G111)/Dane!G111 -> -0.15807293 | G111: =AVERAGE(Dane!H111,Dane!H871,Dane!H1251,Dane!H2011,Dane!H2771,Dane!H3531) -> 115.83333
A112: 1020000 | B112: Powiat zgierski | C112: =(Dane!D3912-Dane!D112)/Dane!D112 -> 0.11173776 | D112: =(Dane!E3912-Dane!E112)/Dane!E112 -> -0.086538462 | E112: =(Dane!F3912-Dane!F112)/Dane!F112 -> 0.2 | F112: =(Dane!G3912-Dane!G112)/Dane!G112 -> -0.29035633 | G112: =AVERAGE(Dane!H112,Dane!H872,Dane!H1252,Dane!H2012,Dane!H2772,Dane!H3532) -> 374
A113: 1021000 | B113: Powiat brzeziński | C113: =(Dane!D3913-Dane!D113)/Dane!D113 -> 0.086254819 | D113: =(Dane!E3913-Dane!E113)/Dane!E113 -> 0.28440367 | E113: =(Dane!F3913-Dane!F113)/Dane!F113 -> 1.2173913 | F113: =(Dane!G3913-Dane!G113)/Dane!G113 -> -0.20974071 | G113: =AVERAGE(Dane!H113,Dane!H873,Dane!H1253,Dane!H2013,Dane!H2773,Dane!H3533) -> 0.66666667
A114: 1061000 | B114: Powiat m. Łódź | C114: =(Dane!D3914-Dane!D114)/Dane!D114 -> 0.095128263 | D114: =(Dane!E3914-Dane!E114)/Dane!E114 -> 2.6264808 | E114: =(Dane!F3914-Dane!F114)/Dane!F114 -> 0.8254707 | F114: =(Dane!G3914-Dane!G114)/Dane!G114 -> -0.025716094 | G114: =AVERAGE(Dane!H114,Dane!H874,Dane!H1254,Dane!H2014,Dane!H2774,Dane!H3534) -> 478.66667
...

Sheet Zmienne pochodne
A1: Suma mieszkań oddannych do użytkowania 2013 - 2023. | B1: Suma remontów mieszkań komunalnych 2013 - 2022. | C1: Różnica zasobów mieszkaniowych pomiędzy rokiem 2013, a 2023.
A2: =SUM(Dane!E2:E4181) -> 2085428 | B2: =SUM(Dane!H2:H4181) -> 117966 | C2: =SUM(Dane!D3802:D4181)-SUM(Dane!D2:D381) -> 1926347
